<?xml version="1.0"?>
<robot xmlns:xacro="http://www.ros.org/wiki/xacro" >
    <xacro:include filename="inertial_macros.xacro" />
    <material name="white">
        <color rgba="1 1 1 1" />
    </material>

    <material name="orange">
        <color rgba="1 0.3 0.1 1"/>
    </material>

    <material name="blue">
        <color rgba="0.2 0.2 1 1"/>
    </material>

    <material name="black">
        <color rgba="0 0 0 1"/>
    </material>

    <material name="red">
        <color rgba="1 0 0 1"/>
    </material>

    <!-- BASE LINK -->

    <link name="base_link">

    </link>

    <joint name="chassis_joint" type="fixed">
        <parent link="base_link"/>
        <child link="chassis"/>
        <origin xyz="0 0 0"/>
        <dynamics damping="1" friction="1"/>
    </joint>

    <link name="chassis">
        <visual>
            <origin xyz="0 0 0.15" rpy="0 0 0"/>
            <geometry>
                <mesh filename="file:///home/white/aufinal_ws/src/articubot_one/description/Body.dae"/>
            </geometry>
            <material name="white"/>
        </visual>
        <collision>
            <origin xyz="0 0 0.15" rpy="0 0 0"/>
            <geometry>
                <mesh filename="file:///home/white/aufinal_ws/src/articubot_one/description/Body.dae"/>
            </geometry>
        </collision>
        <xacro:inertial_box mass="5.0" x="0.2" y="0.2" z="0.25">
            <origin xyz="0 0 0.125" rpy="0 0 0"/>
        </xacro:inertial_box>
    </link>

    <gazebo reference="chassis">
        <material>Gazebo/Blue</material>
        <mu1 value="0.1"/>
        <mu2 value="0.1"/>
    </gazebo>

    <!-- LEFT WHEEL -->
    <!-- Front -->
    <joint name="left_front_wheel_joint" type="continuous">
        <parent link="chassis"/>
        <child link="left_front_wheel"/>
        <origin xyz="-0.125 -0.15 0.025" rpy="0 0 ${pi/2}"/>
        <axis xyz="-1 0 0"/>
        <dynamics damping="1" friction="1"/>
    </joint>

    <link name="left_front_wheel">
        <visual>
            <geometry>
                <mesh filename="file:///home/white/aufinal_ws/src/articubot_one/description/Wheel.dae"/>
            </geometry>
            <material name="black"/>
        </visual>
        <collision>
            <geometry>
                <mesh filename="file:///home/white/aufinal_ws/src/articubot_one/description/Wheel.dae"/>
            </geometry>
        </collision>
        <xacro:inertial_cylinder mass="0.1" length="0.05" radius="0.05">
            <origin xyz="0 0 0" rpy="0 0 0"/>
        </xacro:inertial_cylinder>
    </link>

    <gazebo reference="left_front_wheel">
        <material>Gazebo/Black</material>
        <mu1 value="0.1"/>
        <mu2 value="0.1"/>
    </gazebo>
    
    <!-- Back -->
    <joint name="left_back_wheel_joint" type="continuous">
        <parent link="chassis"/>
        <child link="left_back_wheel"/>
        <origin xyz="0.125 -0.15 0.025" rpy="0 0 ${pi/2}"/>
        <axis xyz="-1 0 0"/>
        <dynamics damping="1" friction="1"/>
    </joint>

    <link name="left_back_wheel">
        <visual>
            <geometry>
                <mesh filename="file:///home/white/aufinal_ws/src/articubot_one/description/Wheel.dae"/>
            </geometry>
            <material name="black"/>
        </visual>
        <collision>
            <geometry>
                <mesh filename="file:///home/white/aufinal_ws/src/articubot_one/description/Wheel.dae"/>
            </geometry>
        </collision>
        <xacro:inertial_cylinder mass="0.1" length="0.05" radius="0.05">
            <origin xyz="0 0 0" rpy="0 0 0"/>
        </xacro:inertial_cylinder>
    </link>

    <gazebo reference="left_back_wheel">
        <material>Gazebo/Black</material>
        <mu1 value="0.1"/>
        <mu2 value="0.1"/>
    </gazebo>

    <!-- RIGHT WHEEl -->
    <!-- Front -->
    <joint name="right_front_wheel_joint" type="continuous">
        <parent link="chassis"/>
        <child link="right_front_wheel"/>
        <origin xyz="-0.15 0.175 0.025" rpy="0 0 ${pi/2}"/>
        <axis xyz="-1 0 0"/>
        <dynamics damping="1" friction="1"/>
    </joint>

    <link name="right_front_wheel">
        <visual>
            <geometry>
                <mesh filename="file:///home/white/aufinal_ws/src/articubot_one/description/Wheel.dae"/>
            </geometry>
            <material name="black"/>
        </visual>
        <collision>
            <geometry>
                <mesh filename="file:///home/white/aufinal_ws/src/articubot_one/description/Wheel.dae"/>
            </geometry>
        </collision>
        <xacro:inertial_cylinder mass="0.1" length="0.05" radius="0.05">
            <origin xyz="0 0 0" rpy="0 0 0"/>
        </xacro:inertial_cylinder>
    </link>

    <gazebo reference="right_front_wheel">
        <material>Gazebo/Black</material>
        <mu1 value="0.1"/>
        <mu2 value="0.1"/>
    </gazebo>
    
    <!-- Back -->
    <joint name="right_back_wheel_joint" type="continuous">
        <parent link="chassis"/>
        <child link="right_back_wheel"/>
        <origin xyz="0.15 0.175 0.025" rpy="0 0 ${pi/2}"/>
        <axis xyz="-1 0 0"/>
        <dynamics damping="1" friction="1"/>
    </joint>

    <link name="right_back_wheel">
        <visual>
            <geometry>
                <mesh filename="file:///home/white/aufinal_ws/src/articubot_one/description/Wheel.dae"/>
            </geometry>
            <material name="black"/>
        </visual>
        <collision>
            <geometry>
                <mesh filename="file:///home/white/aufinal_ws/src/articubot_one/description/Wheel.dae"/>
            </geometry>
        </collision>
        <xacro:inertial_cylinder mass="0.1" length="0.05" radius="0.05">
            <origin xyz="0 0 0" rpy="0 0 0"/>
        </xacro:inertial_cylinder>
    </link>

    <gazebo reference="right_back_wheel">
        <material>Gazebo/Black</material>
        <mu1 value="0.1"/>
        <mu2 value="0.1"/>
    </gazebo>

    <!-- Sup -->
    <joint name="sup_grip_joint" type="prismatic">
        <parent link="chassis"/>
        <child link="sup_grip"/>
        <origin xyz="-0.21 0 0.14" rpy="0 0 0"/>
        <axis xyz="0 0 -1"/>
        <limit lower = "-0.17" upper = "0" effort = "100" velocity="3" />
        <dynamics damping="1" friction="1"/>
    </joint>

    <link name="sup_grip">
        <visual>
            <geometry>
                <mesh filename="file:///home/white/aufinal_ws/src/articubot_one/description/Sup.dae"/>
            </geometry>
            <material name="black"/>
        </visual>
        <collision>
            <geometry>
                <mesh filename="file:///home/white/aufinal_ws/src/articubot_one/description/Sup.dae"/>
            </geometry>
        </collision>
        <xacro:inertial_cylinder mass="0.1" length="0.02" radius="0.05">
            <origin xyz="-0.05 0 0" rpy="0 0 0"/>
        </xacro:inertial_cylinder>
    </link>

    <gazebo reference="sup_grip">
        <material>Gazebo/White</material>
        <mu1 value="0.1"/>
        <mu2 value="0.1"/>
    </gazebo>
    
    <!-- Gripper -->
    <joint name="gripper_joint" type="revolute">
        <parent link="sup_grip"/>
        <child link="gripper"/>
        <origin xyz="-0.0075 0 0" rpy="0 0 0"/>
        <axis xyz="0 1 0"/>
        <limit lower = "0" upper = "3.14" effort = "100" velocity="3" />
        <dynamics damping="1" friction="1"/>
    </joint>

    <link name="gripper">
        <visual>
            <geometry>
                <mesh filename="file:///home/white/aufinal_ws/src/articubot_one/description/Gripper.dae"/>
            </geometry>
            <material name="black"/>
        </visual>
        <collision>
            <geometry>
                <mesh filename="file:///home/white/aufinal_ws/src/articubot_one/description/Gripper.dae"/>
            </geometry>
        </collision>
        <xacro:inertial_cylinder mass="0.1" length="0.02" radius="0.05">
            <origin xyz="-0.1 0 -0.1" rpy="0 0 0"/>
        </xacro:inertial_cylinder>
    </link>

    <gazebo reference="gripper">
        <material>Gazebo/Black</material>
        <mu1 value="0.1"/>
        <mu2 value="0.1"/>
    </gazebo>
    
</robot>